Workbook
Name Slicer_Product_Category: #N/A
Name Slicer_Region: #N/A
Name Slicer_Year: #N/A

Sheet Dashboard
A1: AI-Assisted Business Analytics Dashboard
A3: Sales, Customer & Forecast Insights using Microsoft Excel AI

Sheet Raw_Data
A1: Order_ID | B1: Order_Date | C1: Product_Category | D1: Product_Name | E1: Region | F1: Customer_Segment | G1: Quantity | H1: Sales | I1: Discount | J1: Profit
A2: ORD1001 | B2: 43842 | C2: Electronics | D2: Bluetooth Speaker | E2: North | F2: Consumer | G2: 6 | H2: 4000 | I2: 0.05 | J2: 3800
A3: ORD1002 | B3: 43843 | C3: Electronics | D3: Wireless Mouse | E3: South | F3: Consumer | G3: 2 | H3: 6400 | I3: 0.1 | J3: 5760
A4: ORD1003 | B4: 43844 | C4: Electronics | D4: Keyboard | E4: East | F4: Consumer | G4: 7 | H4: 13900 | I4: 0.15 | J4: 11815
A5: ORD1004 | B5: 43845 | C5: Electronics | D5: Laptop Stand | E5: West | F5: Consumer | G5: 9 | H5: 9500 | I5: 0.2 | J5: 7600
A6: ORD1005 | B6: 43846 | C6: Electronics | D6: USB Flash Drive | E6: North | F6: Consumer | G6: 10 | H6: 5500 | I6: 0.25 | J6: 4125
A7: ORD1006 | B7: 43847 | C7: Electronics | D7: External Hard Disk | E7: South | F7: Consumer | G7: 3 | H7: 9300 | I7: 0.05 | J7: 8835
A8: ORD1007 | B8: 43848 | C8: Electronics | D8: Webcam | E8: East | F8: Consumer | G8: 9 | H8: 13500 | I8: 0.1 | J8: 12150
A9: ORD1008 | B9: 43849 | C9: Electronics | D9: Noise Cancelling Headphones | E9: West | F9: Consumer | G9: 3 | H9: 12400 | I9: 0.15 | J9: 10540
A10: ORD1009 | B10: 43850 | C10: Electronics | D10: Smart Watch | E10: North | F10: Consumer | G10: 9 | H10: 9400 | I10: 0.2 | J10: 7520
A11: ORD1010 | B11: 43851 | C11: Electronics | D11: Portable Power Bank | E11: South | F11: Consumer | G11: 1 | H11: 5400 | I11: 0.25 | J11: 4050
A12: ORD1011 | B12: 43852 | C12: Furniture | D12: Office Chair | E12: East | F12: Corporate | G12: 8 | H12: 6200 | I12: 0.05 | J12: 5890
A13: ORD1012 | B13: 43853 | C13: Furniture | D13: Study Table | E13: West | F13: Corporate | G13: 2 | H13: 14500 | I13: 0.1 | J13: 13050
... A2001: ORD3000 | B2001: 45841 | C2001: Furniture | D2001: Office Sofa | E2001: West | F2001: Corporate | G2001: 1 | H2001: 10400 | I2001: 0.25 | J2001: 7800

Sheet Cleaned_Data
A1: Order_ID | B1: Order_Date | C1: Year | D1: Month | E1: Product_Category | F1: Product_Name | G1: Region | H1: Customer_Segment | I1: Quantity | J1: Sales | K1: Discount | L1: Profit | M1: Profit_Margin | N1: Sales_Band | O1: Forecast_Date | P1: Forecast_Sales
A2: ORD1001 | B2: 43842 | C2: 2020 | D2: =TEXT(B2,"MMM") -> Jan | E2: Electronics | F2: Bluetooth Speaker | G2: North | H2: Consumer | I2: 6 | J2: 4000 | K2: 0.05 | L2: 3800 | M2: =Sales_Data3[[#This Row],[Profit]]/Sales_Data3[[#This Row],[Sales]] -> 0.95 | N2: =IF(J2>10000,"High",IF(J2>5000,"Medium","Low")) -> Low | O2: 43842 | P2: 4000
A3: ORD1002 | B3: 43843 | C3: 2020 | D3: =TEXT(B3,"MMM") -> Jan | E3: Electronics | F3: Wireless Mouse | G3: South | H3: Consumer | I3: 2 | J3: 6400 | K3: 0.1 | L3: 5760 | M3: =Sales_Data3[[#This Row],[Profit]]/Sales_Data3[[#This Row],[Sales]] -> 0.9 | N3: =IF(J3>10000,"High",IF(J3>5000,"Medium","Low")) -> Medium | O3: 43843 | P3: 6400
A4: ORD1003 | B4: 43844 | C4: 2020 | D4: =TEXT(B4,"MMM") -> Jan | E4: Electronics | F4: Keyboard | G4: East | H4: Consumer | I4: 7 | J4: 13900 | K4: 0.15 | L4: 11815 | M4: =Sales_Data3[[#This Row],[Profit]]/Sales_Data3[[#This Row],[Sales]] -> 0.85 | N4: =IF(J4>10000,"High",IF(J4>5000,"Medium","Low")) -> High | O4: 43844 | P4: 13900
A5: ORD1004 | B5: 43845 | C5: 2020 | D5: =TEXT(B5,"MMM") -> Jan | E5: Electronics | F5: Laptop Stand | G5: West | H5: Consumer | I5: 9 | J5: 9500 | K5: 0.2 | L5: 7600 | M5: =Sales_Data3[[#This Row],[Profit]]/Sales_Data3[[#This Row],[Sales]] -> 0.8 | N5: =IF(J5>10000,"High",IF(J5>5000,"Medium","Low")) -> Medium | O5: 43845 | P5: 9500
A6: ORD1005 | B6: 43846 | C6: 2020 | D6: =TEXT(B6,"MMM") -> Jan | E6: Electronics | F6: USB Flash Drive | G6: North | H6: Consumer | I6: 10 | J6: 5500 | K6: 0.25 | L6: 4125 | M6: =Sales_Data3[[#This Row],[Profit]]/Sales_Data3[[#This Row],[Sales]] -> 0.75 | N6: =IF(J6>10000,"High",IF(J6>5000,"Medium","Low")) -> Medium | O6: 43846 | P6: 5500
A7: ORD1006 | B7: 43847 | C7: 2020 | D7: =TEXT(B7,"MMM") -> Jan | E7: Electronics | F7: External Hard Disk | G7: South | H7: Consumer | I7: 3 | J7: 9300 | K7: 0.05 | L7: 8835 | M7: =Sales_Data3[[#This Row],[Profit]]/Sales_Data3[[#This Row],[Sales]] -> 0.95 | N7: =IF(J7>10000,"High",IF(J7>5000,"Medium","Low")) -> Medium | O7: 43847 | P7: 9300
A8: ORD1007 | B8: 43848 | C8: 2020 | D8: =TEXT(B8,"MMM") -> Jan | E8: Electronics | F8: Webcam | G8: East | H8: Consumer | I8: 9 | J8: 13500 | K8: 0.1 | L8: 12150 | M8: =Sales_Data3[[#This Row],[Profit]]/Sales_Data3[[#This Row],[Sales]] -> 0.9 | N8: =IF(J8>10000,"High",IF(J8>5000,"Medium","Low")) -> High | O8: 43848 | P8: 13500
A9: ORD1008 | B9: 43849 | C9: 2020 | D9: =TEXT(B9,"MMM") -> Jan | E9: Electronics | F9: Noise Cancelling Headphones | G9: West | H9: Consumer | I9: 3 | J9: 12400 | K9: 0.15 | L9: 10540 | M9: =Sales_Data3[[#This Row],[Profit]]/Sales_Data3[[#This Row],[Sales]] -> 0.85 | N9: =IF(J9>10000,"High",IF(J9>5000,"Medium","Low")) -> High | O9: 43849 | P9: 12400
A10: ORD1009 | B10: 43850 | C10: 2020 | D10: =TEXT(B10,"MMM") -> Jan | E10: Electronics | F10: Smart Watch | G10: North | H10: Consumer | I10: 9 | J10: 9400 | K10: 0.2 | L10: 7520 | M10: =Sales_Data3[[#This Row],[Profit]]/Sales_Data3[[#This Row],[Sales]] -> 0.8 | N10: =IF(J10>10000,"High",IF(J10>5000,"Medium","Low")) -> Medium | O10: 43850 | P10: 9400
A11: ORD1010 | B11: 43851 | C11: 2020 | D11: =TEXT(B11,"MMM") -> Jan | E11: Electronics | F11: Portable Power Bank | G11: South | H11: Consumer | I11: 1 | J11: 5400 | K11: 0.25 | L11: 4050 | M11: =Sales_Data3[[#This Row],[Profit]]/Sales_Data3[[#This Row],[Sales]] -> 0.75 | N11: =IF(J11>10000,"High",IF(J11>5000,"Medium","Low")) -> Medium | O11: 43851 | P11: 5400
A12: ORD1011 | B12: 43852 | C12: 2020 | D12: =TEXT(B12,"MMM") -> Jan | E12: Furniture | F12: Office Chair | G12: East | H12: Corporate | I12: 8 | J12: 6200 | K12: 0.05 | L12: 5890 | M12: =Sales_Data3[[#This Row],[Profit]]/Sales_Data3[[#This Row],[Sales]] -> 0.95 | N12: =IF(J12>10000,"High",IF(J12>5000,"Medium","Low")) -> Medium | O12: 43852 | P12: 6200
A13: ORD1012 | B13: 43853 | C13: 2020 | D13: =TEXT(B13,"MMM") -> Jan | E13: Furniture | F13: Study Table | G13: West | H13: Corporate | I13: 2 | J13: 14500 | K13: 0.1 | L13: 13050 | M13: =Sales_Data3[[#This Row],[Profit]]/Sales_Data3[[#This Row],[Sales]] -> 0.9 | N13: =IF(J13>10000,"High",IF(J13>5000,"Medium","Low")) -> High | O13: 43853 | P13: 14500
... A2001: ORD3000 | B2001: 45841 | C2001: 2025 | D2001: =TEXT(B2001,"MMM") -> Jul | E2001: Furniture | F2001: Office Sofa | G2001: West | H2001: Corporate | I2001: 1 | J2001: 10400 | K2001: 0.25 | L2001: 7800 | M2001: =Sales_Data3[[#This Row],[Profit]]/Sales_Data3[[#This Row],[Sales]] -> 0.75 | N2001: =IF(J2001>10000,"High",IF(J2001>5000,"Medium","Low")) -> High | O2001: 45841 | P2001: 10400

Sheet Pivot_Analysis
A1: Sales Trend (Year-Month) | D1: Region Performance | H1: Category Analysis | L1: Customer Segment Sales | P1: Average of Discount
A2: Row Labels | B2: Sum of Sales | D2: Row Labels | E2: Sum of Sales | F2: Sum of Profit | H2: Row Labels | I2: Sum of Sales | J2: Profit_Margin | L2: Row Labels | M2: Sum of Sales | P2: 0.15
A3: 2020 | B3: 3354600 | D3: East | E3: 4834800 | F3: 4108925 | H3: Electronics | I3: 6436500 | J3: 0.85 | L3: Consumer | M3: 6436500
A4: Jan | B4: 191600 | D4: North | E4: 4713200 | F4: 4008795 | H4: Furniture | I4: 6384400 | J4: 0.85 | L4: Corporate | M4: 6384400
A5: Feb | B5: 266700 | D5: South | E5: 4778000 | F5: 4052705 | H5: Office Supplies | I5: 6252700 | J5: 0.85 | L5: Home Office | M5: 6252700
A6: Mar | B6: 304600 | D6: West | E6: 4747600 | F6: 4038670
A7: Apr | B7: 300000
A8: May | B8: 295000
A9: Jun | B9: 265800
A10: Jul | B10: 318800
A11: Aug | B11: 307500
A12: Sep | B12: 281400
A13: Oct | B13: 263700
A14: Nov | B14: 295500
A15: Dec | B15: 264000
A16: 2021 | B16: 3566300
A17: Jan | B17: 319900
A18: Feb | B18: 285700
A19: Mar | B19: 308400
A20: Apr | B20: 260000
A21: May | B21: 305500
A22: Jun | B22: 294600
A23: Jul | B23: 328100
A24: Aug | B24: 303600
A25: Sep | B25: 286000
A26: Oct | B26: 300100
A27: Nov | B27: 296900
A28: Dec | B28: 277500
A29: 2022 | B29: 3432200
A30: Jan | B30: 283000
A31: Feb | B31: 253700
A32: Mar | B32: 285900
A33: Apr | B33: 282900
A34: May | B34: 274800
A35: Jun | B35: 289700
A36: Jul | B36: 290100
A37: Aug | B37: 302700
A38: Sep | B38: 304900
A39: Oct | B39: 286100
A40: Nov | B40: 279700
...

Sheet AI_Forecast
A1: Forecast_Date | B1: Forecast_Sales | C1: Forecast(Forecast_Sales) | D1: Lower Confidence Bound(Forecast_Sales) | E1: Upper Confidence Bound(Forecast_Sales)
A2: 43842 | B2: 4000
A3: 43843 | B3: 6400
A4: 43844 | B4: 13900
A5: 43845 | B5: 9500
A6: 43846 | B6: 5500
A7: 43847 | B7: 9300
A8: 43848 | B8: 13500
A9: 43849 | B9: 12400
A10: 43850 | B10: 9400
A11: 43851 | B11: 5400
A12: 43852 | B12: 6200
A13: 43853 | B13: 14500
... A2000: 45840 | B2000: 13600
A2001: 45841 | B2001: 10400 | C2001: 10400 | D2001: 10400 | E2001: 10400
A2002: 45842 | C2002: =_xlfn.FORECAST.ETS(A2002,$B$2:$B$2001,$A$2:$A$2001,12,1) -> 7895.2901 | D2002: =C2002-_xlfn.FORECAST.ETS.CONFINT(A2002,$B$2:$B$2001,$A$2:$A$2001,0.95,12,1) -> 889.75657 | E2002: =C2002+_xlfn.FORECAST.ETS.CONFINT(A2002,$B$2:$B$2001,$A$2:$A$2001,0.95,12,1) -> 14900.824
A2003: 45843 | C2003: =_xlfn.FORECAST.ETS(A2003,$B$2:$B$2001,$A$2:$A$2001,12,1) -> 7948.2504 | D2003: =C2003-_xlfn.FORECAST.ETS.CONFINT(A2003,$B$2:$B$2001,$A$2:$A$2001,0.95,12,1) -> 942.68531 | E2003: =C2003+_xlfn.FORECAST.ETS.CONFINT(A2003,$B$2:$B$2001,$A$2:$A$2001,0.95,12,1) -> 14953.815
A2004: 45844 | C2004: =_xlfn.FORECAST.ETS(A2004,$B$2:$B$2001,$A$2:$A$2001,12,1) -> 8095.3812 | D2004: =C2004-_xlfn.FORECAST.ETS.CONFINT(A2004,$B$2:$B$2001,$A$2:$A$2001,0.95,12,1) -> 1089.76 | E2004: =C2004+_xlfn.FORECAST.ETS.CONFINT(A2004,$B$2:$B$2001,$A$2:$A$2001,0.95,12,1) -> 15101.002
A2005: 45845 | C2005: =_xlfn.FORECAST.ETS(A2005,$B$2:$B$2001,$A$2:$A$2001,12,1) -> 7869.8758 | D2005: =C2005-_xlfn.FORECAST.ETS.CONFINT(A2005,$B$2:$B$2001,$A$2:$A$2001,0.95,12,1) -> 864.16709 | E2005: =C2005+_xlfn.FORECAST.ETS.CONFINT(A2005,$B$2:$B$2001,$A$2:$A$2001,0.95,12,1) -> 14875.584
A2006: 45846 | C2006: =_xlfn.FORECAST.ETS(A2006,$B$2:$B$2001,$A$2:$A$2001,12,1) -> 6190.0071 | D2006: =C2006-_xlfn.FORECAST.ETS.CONFINT(A2006,$B$2:$B$2001,$A$2:$A$2001,0.95,12,1) -> -815.82768 | E2006: =C2006+_xlfn.FORECAST.ETS.CONFINT(A2006,$B$2:$B$2001,$A$2:$A$2001,0.95,12,1) -> 13195.842
A2007: 45847 | C2007: =_xlfn.FORECAST.ETS(A2007,$B$2:$B$2001,$A$2:$A$2001,12,1) -> 6023.5747 | D2007: =C2007-_xlfn.FORECAST.ETS.CONFINT(A2007,$B$2:$B$2001,$A$2:$A$2001,0.95,12,1) -> -982.43169 | E2007: =C2007+_xlfn.FORECAST.ETS.CONFINT(A2007,$B$2:$B$2001,$A$2:$A$2001,0.95,12,1) -> 13029.581
A2008: 45848 | C2008: =_xlfn.FORECAST.ETS(A2008,$B$2:$B$2001,$A$2:$A$2001,12,1) -> 9810.0176 | D2008: =C2008-_xlfn.FORECAST.ETS.CONFINT(A2008,$B$2:$B$2001,$A$2:$A$2001,0.95,12,1) -> 2803.787 | E2008: =C2008+_xlfn.FORECAST.ETS.CONFINT(A2008,$B$2:$B$2001,$A$2:$A$2001,0.95,12,1) -> 16816.248
A2009: 45849 | C2009: =_xlfn.FORECAST.ETS(A2009,$B$2:$B$2001,$A$2:$A$2001,12,1) -> 8783.9897 | D2009: =C2009-_xlfn.FORECAST.ETS.CONFINT(A2009,$B$2:$B$2001,$A$2:$A$2001,0.95,12,1) -> 1777.4755 | E2009: =C2009+_xlfn.FORECAST.ETS.CONFINT(A2009,$B$2:$B$2001,$A$2:$A$2001,0.95,12,1) -> 15790.504
A2010: 45850 | C2010: =_xlfn.FORECAST.ETS(A2010,$B$2:$B$2001,$A$2:$A$2001,12,1) -> 7900.772 | D2010: =C2010-_xlfn.FORECAST.ETS.CONFINT(A2010,$B$2:$B$2001,$A$2:$A$2001,0.95,12,1) -> 893.90753 | E2010: =C2010+_xlfn.FORECAST.ETS.CONFINT(A2010,$B$2:$B$2001,$A$2:$A$2001,0.95,12,1) -> 14907.637
A2011: 45851 | C2011: =_xlfn.FORECAST.ETS(A2011,$B$2:$B$2001,$A$2:$A$2001,12,1) -> 7372.1946 | D2011: =C2011-_xlfn.FORECAST.ETS.CONFINT(A2011,$B$2:$B$2001,$A$2:$A$2001,0.95,12,1) -> 364.90637 | E2011: =C2011+_xlfn.FORECAST.ETS.CONFINT(A2011,$B$2:$B$2001,$A$2:$A$2001,0.95,12,1) -> 14379.483
A2012: 45852 | C2012: =_xlfn.FORECAST.ETS(A2012,$B$2:$B$2001,$A$2:$A$2001,12,1) -> 8733.9497 | D2012: =C2012-_xlfn.FORECAST.ETS.CONFINT(A2012,$B$2:$B$2001,$A$2:$A$2001,0.95,12,1) -> 1726.1572 | E2012: =C2012+_xlfn.FORECAST.ETS.CONFINT(A2012,$B$2:$B$2001,$A$2:$A$2001,0.95,12,1) -> 15741.742
A2013: 45853 | C2013: =_xlfn.FORECAST.ETS(A2013,$B$2:$B$2001,$A$2:$A$2001,12,1) -> 10399.321 | D2013: =C2013-_xlfn.FORECAST.ETS.CONFINT(A2013,$B$2:$B$2001,$A$2:$A$2001,0.95,12,1) -> 3390.9363 | E2013: =C2013+_xlfn.FORECAST.ETS.CONFINT(A2013,$B$2:$B$2001,$A$2:$A$2001,0.95,12,1) -> 17407.705
... A2367: 46207 | C2367: =_xlfn.FORECAST.ETS(A2367,$B$2:$B$2001,$A$2:$A$2001,12,1) -> 6003.1914 | D2367: =C2367-_xlfn.FORECAST.ETS.CONFINT(A2367,$B$2:$B$2001,$A$2:$A$2001,0.95,12,1) -> -27033.939 | E2367: =C2367+_xlfn.FORECAST.ETS.CONFINT(A2367,$B$2:$B$2001,$A$2:$A$2001,0.95,12,1) -> 39040.321

Sheet AI_Insights
A2: North Sales | B2: =GETPIVOTDATA("Sum of Sales",Pivot_Analysis!$D$2,"Region","North") -> 4713200
A3: North Profit | B3: =GETPIVOTDATA("Sum of Profit",Pivot_Analysis!$D$2,"Region","North") -> 4008795
A5: North Region Insight | B5: =IF(B3/B2<0.15,"⚠ North region has low profitability","✔ North region is performing well") -> ✔ North region is performing well
A7: Average Profit Margin | B7: =GETPIVOTDATA("[Measures].[Average of Profit_Margin]",Pivot_Analysis!$H$2,"[Sales_Data3].[Product_Category]","[Sales_Data3].[Product_Category].&[Electronics]") -> 0.85
A8: Discount Insight | B8: =IF(B7<0.2,"⚠ High discounts are reducing profitability","✔ Discount strategy is healthy") -> ✔ Discount strategy is healthy
A10: Best Category | B10: =Pivot_Analysis!H3 -> Electronics
B11: ="↗Best Performing Category: "&B10 -> ↗Best Performing Category: Electronics
A13: Lowest Performing Customer Segment | B13: =Pivot_Analysis!L5 -> Home Office
B14: ="↘ Lowest Performing Customer Segment: "&B13 -> ↘ Lowest Performing Customer Segment: Home Office
A16: Forecast Method Explanation | B16: Tool used: Excel Forecast Sheet / ETS
B18: Basis: Historical monthly sales
B20: Assumption: Seasonality considered
B22: Confidence Interval: 95%

Sheet Recommendations
A1: Metric | B1: Value | C1: Recommendation
A2: Profit Margin | B2: =GETPIVOTDATA("[Measures].[Average of Profit_Margin]",Pivot_Analysis!$H$2,"[Sales_Data3].[Product_Category]","[Sales_Data3].[Product_Category].&[Electronics]") -> 0.85 | C2: =IF(B2<0.1,"Reduce discounts or costs","Maintain current pricing") -> Maintain current pricing
A3: Avg Discount | B3: =GETPIVOTDATA("Discount",Pivot_Analysis!$P$1) -> 0.15 | C3: =IF(B3>0.2,"High discounts hurting profit","Discount level acceptable") -> Discount level acceptable
A4: Top Region | B4: =Pivot_Analysis!D3 -> East | C4: ="Promote products in "&B4&" region" -> Promote products in East region
A5: Top Category | B5: =Pivot_Analysis!H3 -> Electronics | C5: ="Increase inventory and ads for "&B5 -> Increase inventory and ads for Electronics
A6: Weak Segment | B6: =Pivot_Analysis!L5 -> Home Office | C6: ="Re-strategize offers for "&B6&" customers" -> Re-strategize offers for Home Office customers
